Workbook
Name enum_ana_techno: OFFSET(_enum!$A$3,0,0,COUNTA(_enum!$A:$A)-2,1)
Name enum_cap_dielectric: OFFSET(_enum!$D$3,0,0,COUNTA(_enum!$D:$D)-2,1)
Name enum_cap_techno: OFFSET(_enum!$G$3,0,0,COUNTA(_enum!$G:$G)-2,1)
Name enum_dio_techno: OFFSET(_enum!$J$3,0,0,COUNTA(_enum!$J:$J)-2,1)
Name enum_ics_techno: OFFSET(_enum!$M$3,0,0,COUNTA(_enum!$M:$M)-2,1)
Name enum_ind_techno: OFFSET(_enum!$P$3,0,0,COUNTA(_enum!$P:$P)-2,1)
Name enum_lcsc_type: OFFSET(_enum!$AN$3,0,0,COUNTA(_enum!$AN:$AN)-2,1)
Name enum_mfn: OFFSET(_enum!$S$3,0,0,COUNTA(_enum!$S:$S)-2,1)
Name enum_mount_type: OFFSET(_enum!$V$3,0,0,COUNTA(_enum!$V:$V)-2,1)
Name enum_package: OFFSET(_enum!$Y$3,0,0,COUNTA(_enum!$Y:$Y)-2,1)
Name enum_reg_techno: OFFSET(_enum!$AB$3,0,0,COUNTA(_enum!$AB:$AB)-2,1)
Name enum_res_techno: OFFSET(_enum!$AE$3,0,0,COUNTA(_enum!$AE:$AE)-2,1)
Name enum_status: OFFSET(_enum!$AH$3,0,0,COUNTA(_enum!$AH:$AH)-2,1)
Name enum_trn_techno: OFFSET(_enum!$AK$3,0,0,COUNTA(_enum!$AK:$AK)-2,1)

Sheet Index
A1: Code | B1: Sheet | C1: Database Table (sqlite) | D1: Description | E1: Row Count | I1: LEGEND
A2: ANA | B2: ANA | C2: Analog | D2: Op-amps, Comparators, A/D, D/A | E2: =COUNTIF(INDIRECT(_xlfn.CONCAT(B2,"!A:A")), "*")-1 -> 1 | I2: FORMULA
A3: CAP | B3: CAP | C3: Capacitor | D3: Capacitors | E3: =COUNTIF(INDIRECT(_xlfn.CONCAT(B3,"!A:A")), "*")-1 -> 26
A4: CNT | B4: CNT | C4: Connector | D4: Connectors | E4: =COUNTIF(INDIRECT(_xlfn.CONCAT(B4,"!A:A")), "*")-1 -> 7
A5: CPD | B5: CPD | C5: Protection | D5: Circuit Protection Devices (MOV, Varistor, Fuse, etc) | E5: =COUNTIF(INDIRECT(_xlfn.CONCAT(B5,"!A:A")), "*")-1 -> 0
A6: DIO | B6: DIO | C6: Diode | D6: Diodes (Zener, TVS, LED, Schottky, Standard) | E6: =COUNTIF(INDIRECT(_xlfn.CONCAT(B6,"!A:A")), "*")-1 -> 14
A7: FAB | B7: FAB | C7: Fabrication | D7: Fabrication specific elements (Fiducial, Tooling Holes, Mouse Bites) | E7: =COUNTIF(INDIRECT(_xlfn.CONCAT(B7,"!A:A")), "*")-1 -> 7
A8: ICS | B8: ICS | C8: IntegratedCircuit | D8: General Integrated Circuits | E8: =COUNTIF(INDIRECT(_xlfn.CONCAT(B8,"!A:A")), "*")-1 -> 4
A9: IND | B9: IND | C9: Magnetics | D9: Inductors, Transformers, Chokes, Magnetics | E9: =COUNTIF(INDIRECT(_xlfn.CONCAT(B9,"!A:A")), "*")-1 -> 2
A10: MCU | B10: MCU | C10: Microcontroller | D10: Microcontrollers, Modules, etc. | E10: =COUNTIF(INDIRECT(_xlfn.CONCAT(B10,"!A:A")), "*")-1 -> 1
A11: MEC | B11: MEC | C11: Mechanical | D11: Mechanical components (Mounting holes, etc) | E11: =COUNTIF(INDIRECT(_xlfn.CONCAT(B11,"!A:A")), "*")-1 -> 0
A12: MRK | B12: MRK | C12: Marking | D12: Symbols, Logos and Graphics... ie Non-BOM | E12: =COUNTIF(INDIRECT(_xlfn.CONCAT(B12,"!A:A")), "*")-1 -> 7
A13: OPT | B13: OPT | C13: Optoelectronics | D13: Optocouplers, phototransistor, SSR etc. | E13: =COUNTIF(INDIRECT(_xlfn.CONCAT(B13,"!A:A")), "*")-1 -> 0
A14: OSC | B14: OSC | C14: Oscillator | D14: Oscillators, Crystals | E14: =COUNTIF(INDIRECT(_xlfn.CONCAT(B14,"!A:A")), "*")-1 -> 0
... A22: TRN | B22: TRN | C22: Transistor | D22: BJT, FET, IGBT | E22: =COUNTIF(INDIRECT(_xlfn.CONCAT(B22,"!A:A")), "*")-1 -> 7

Sheet ANA
A1: IPN | B1: Description | C1: FLAG - Has Basic Part | D1: Value | E1: Case/Package Size | F1: Type | G1: Symbols | H1: Footprints | I1: Datasheet | J1: MFN_1 | K1: MPN_1 | L1: LCSC_1 | M1: LCSC_TYPE_1 | N1: Status_1 | O1: MFN_2 | P1: MPN_2 | Q1: LCSC_2 | R1: LCSC_TYPE_2 | S1: Status_2 | T1: MFN_3 | U1: MPN_3 | V1: LCSC_3 | W1: LCSC_TYPE_3 | X1: Status_3 | Y1: MFN_4 | Z1: MPN_4 | AA1: LCSC_4 | AB1: LCSC_TYPE_4 | AC1: Status_4 | AD1: Comment
A2: ANA-101-0000 | B2: Opamp, GBWP 370kHz, RRO, 10V | C2: =OR(AND(M2=_enum!$AN$3,OR(N2=_enum!$AH$7,N2=_enum!$AH$3)),AND(R2=_enum!$AN$3,OR(S2=_enum!$AH$7,S2=_enum!$AH$3)),AND(W2=_enum!$AN$3,OR(X2=_enum!$AH$7,X2=_enum!$AH$3)), AND(AB2=_enum!$AN$3,OR(AC2=_enum!$AH$7,AC2=_enum!$AH$3))) -> FALSE | D2: =SUBSTITUTE(A2,"-","") -> ANA1010000 | E2: SOT23-5 | F2: Opamp | G2: 0-ANA:SYM-ANA-0000 | H2: 1-PACKAGES:Generic-SOT-23-5 | I2: https://ww1.microchip.com/downloads/en/DeviceDoc/MIC7300-High-Output-Drive-Rail-to-Rail-Op-Amp-DS20006305A.pdf | J2: Microchip | K2: MIC7300YM5_ | L2: C145391 | M2: BASIC | N2: Candidate
D3: =SUBSTITUTE(A3,"-","")
D4: =SUBSTITUTE(A4,"-","")
D5: =SUBSTITUTE(A5,"-","")
D6: =SUBSTITUTE(A6,"-","")
D7: =SUBSTITUTE(A7,"-","")
D8: =SUBSTITUTE(A8,"-","")
D9: =SUBSTITUTE(A9,"-","")
D10: =SUBSTITUTE(A10,"-","")
D11: =SUBSTITUTE(A11,"-","")
D12: =SUBSTITUTE(A12,"-","")
D13: =SUBSTITUTE(A13,"-","")
D14: =SUBSTITUTE(A14,"-","")
... D29: =SUBSTITUTE(A29,"-","")

Sheet CAP
A1: IPN | B1: Description | C1: FLAG - Has Basic Part | D1: Value | E1: Capacitance [nF] | F1: Voltage Rating [V] | G1: Type | H1: Dielectric | I1: Tolerance [%] | J1: Case/Package Size | K1: Symbols | L1: Footprints | M1: Datasheet | N1: MFN_1 | O1: MPN_1 | P1: LCSC_1 | Q1: LCSC_TYPE_1 | R1: Status_1 | S1: MFN_2 | T1: MPN_2 | U1: LCSC_2 | V1: LCSC_TYPE_2 | W1: Status_2 | X1: MFN_3 | Y1: MPN_3 | Z1: LCSC_3 | AA1: LCSC_TYPE_3 | AB1: Status_3 | AC1: MFN_4 | AD1: MPN_4 | AE1: LCSC_4 | AF1: LCSC_TYPE_4 | AG1: Status_4 | AH1: Comment
A2: CAP-000-1042 | B2: =_xlfn.CONCAT("Cap ",G2," ",D2,"F ",F2," ",H2," ",J2,IF(C2," - BASIC","")) -> Cap Cer 100nF 50V X7R 0603 - BASIC | C2: =OR(AND(Q2=_enum!$AN$3,OR(R2=_enum!$AH$7,R2=_enum!$AH$3)),AND(V2=_enum!$AN$3,OR(W2=_enum!$AH$7,W2=_enum!$AH$3)),AND(AA2=_enum!$AN$3,OR(AB2=_enum!$AH$7,AB2=_enum!$AH$3)), AND(AF2=_enum!$AN$3,OR(AG2=_enum!$AH$7,AG2=_enum!$AH$3))) -> TRUE | D2: 100n | E2: {=IF(OR(D2="",D2="TBD"),"", _xlfn.LET( _xlpm.s,LOWER(TRIM(D2)), _xlpm.num,VALUE(LEFT(_xlpm.s,LEN(_xlpm.s)-1)), _xlpm.unit,RIGHT(_xlpm.s,1), _xlfn.SWITCH(_xlpm.unit, "p",_xlpm.num/1000, "n",_xlpm.num, "u",_xlpm.num*1000, D2) ))} -> 100 | F2: 50V | G2: Cer | H2: X7R | I2: 10 | J2: 0603 | K2: 0-CAP:SYM-CAP-0000 | L2: 0-CAP:FTP-CAP-0001 | M2: ~ | N2: Samsung | O2: CC0603KRX7R9BB104 | P2: C14663 | Q2: BASIC | R2: Preferred
A3: CAP-001-1032 | B3: =_xlfn.CONCAT("Cap ",G3," ",D3,"F ",F3," ",H3," ",J3,IF(C3," - BASIC","")) -> Cap Cer 10nF 50V X7R 0402 - BASIC | C3: =OR(AND(Q3=_enum!$AN$3,OR(R3=_enum!$AH$7,R3=_enum!$AH$3)),AND(V3=_enum!$AN$3,OR(W3=_enum!$AH$7,W3=_enum!$AH$3)),AND(AA3=_enum!$AN$3,OR(AB3=_enum!$AH$7,AB3=_enum!$AH$3)), AND(AF3=_enum!$AN$3,OR(AG3=_enum!$AH$7,AG3=_enum!$AH$3))) -> TRUE | D3: 10n | E3: {=IF(OR(D3="",D3="TBD"),"", _xlfn.LET( _xlpm.s,LOWER(TRIM(D3)), _xlpm.num,VALUE(LEFT(_xlpm.s,LEN(_xlpm.s)-1)), _xlpm.unit,RIGHT(_xlpm.s,1), _xlfn.SWITCH(_xlpm.unit, "p",_xlpm.num/1000, "n",_xlpm.num, "u",_xlpm.num*1000, D3) ))} -> 10 | F3: 50V | G3: Cer | H3: X7R | I3: 10 | J3: 0402 | K3: 0-CAP:SYM-CAP-0000 | L3: 0-CAP:FTP-CAP-0000 | M3: ~ | N3: Samsung | O3: CL05B103KB5NNNC | P3: C15195 | Q3: BASIC | R3: Preferred
A4: CAP-001-1042 | B4: =_xlfn.CONCAT("Cap ",G4," ",D4,"F ",F4," ",H4," ",J4,IF(C4," - BASIC","")) -> Cap Cer 100nF 50V X7R 0402 - BASIC | C4: =OR(AND(Q4=_enum!$AN$3,OR(R4=_enum!$AH$7,R4=_enum!$AH$3)),AND(V4=_enum!$AN$3,OR(W4=_enum!$AH$7,W4=_enum!$AH$3)),AND(AA4=_enum!$AN$3,OR(AB4=_enum!$AH$7,AB4=_enum!$AH$3)), AND(AF4=_enum!$AN$3,OR(AG4=_enum!$AH$7,AG4=_enum!$AH$3))) -> TRUE | D4: 100n | E4: {=IF(OR(D4="",D4="TBD"),"", _xlfn.LET( _xlpm.s,LOWER(TRIM(D4)), _xlpm.num,VALUE(LEFT(_xlpm.s,LEN(_xlpm.s)-1)), _xlpm.unit,RIGHT(_xlpm.s,1), _xlfn.SWITCH(_xlpm.unit, "p",_xlpm.num/1000, "n",_xlpm.num, "u",_xlpm.num*1000, D4) ))} -> 100 | F4: 50V | G4: Cer | H4: X7R | I4: 10 | J4: 0402 | K4: 0-CAP:SYM-CAP-0000 | L4: 0-CAP:FTP-CAP-0000 | M4: ~ | N4: Samsung | O4: CL05B104KB54PNC | P4: C307331 | Q4: BASIC | R4: Preferred
A5: CAP-002-1003 | B5: =_xlfn.CONCAT("Cap ",G5," ",D5,"F ",F5," ",H5," ",J5,IF(C5," - BASIC","")) -> Cap Cer 10pF 50V C0G/NP0 0402 - BASIC | C5: =OR(AND(Q5=_enum!$AN$3,OR(R5=_enum!$AH$7,R5=_enum!$AH$3)),AND(V5=_enum!$AN$3,OR(W5=_enum!$AH$7,W5=_enum!$AH$3)),AND(AA5=_enum!$AN$3,OR(AB5=_enum!$AH$7,AB5=_enum!$AH$3)), AND(AF5=_enum!$AN$3,OR(AG5=_enum!$AH$7,AG5=_enum!$AH$3))) -> TRUE | D5: 10p | E5: {=IF(OR(D5="",D5="TBD"),"", _xlfn.LET( _xlpm.s,LOWER(TRIM(D5)), _xlpm.num,VALUE(LEFT(_xlpm.s,LEN(_xlpm.s)-1)), _xlpm.unit,RIGHT(_xlpm.s,1), _xlfn.SWITCH(_xlpm.unit, "p",_xlpm.num/1000, "n",_xlpm.num, "u",_xlpm.num*1000, D5) ))} -> 0.01 | F5: 50V | G5: Cer | H5: C0G/NP0 | I5: 5 | J5: 0402 | K5: 0-CAP:SYM-CAP-0000 | L5: 0-CAP:FTP-CAP-0000 | M5: ~ | N5: Samsung | O5: CL05C100JB5NNNC | P5: C32949 | Q5: BASIC | R5: Preferred
A6: CAP-002-1013 | B6: =_xlfn.CONCAT("Cap ",G6," ",D6,"F ",F6," ",H6," ",J6,IF(C6," - BASIC","")) -> Cap Cer 100pF 50V C0G/NP0 0402 - BASIC | C6: =OR(AND(Q6=_enum!$AN$3,OR(R6=_enum!$AH$7,R6=_enum!$AH$3)),AND(V6=_enum!$AN$3,OR(W6=_enum!$AH$7,W6=_enum!$AH$3)),AND(AA6=_enum!$AN$3,OR(AB6=_enum!$AH$7,AB6=_enum!$AH$3)), AND(AF6=_enum!$AN$3,OR(AG6=_enum!$AH$7,AG6=_enum!$AH$3))) -> TRUE | D6: 100p | E6: {=IF(OR(D6="",D6="TBD"),"", _xlfn.LET( _xlpm.s,LOWER(TRIM(D6)), _xlpm.num,VALUE(LEFT(_xlpm.s,LEN(_xlpm.s)-1)), _xlpm.unit,RIGHT(_xlpm.s,1), _xlfn.SWITCH(_xlpm.unit, "p",_xlpm.num/1000, "n",_xlpm.num, "u",_xlpm.num*1000, D6) ))} -> 0.1 | F6: 50V | G6: Cer | H6: C0G/NP0 | I6: 5 | J6: 0402 | K6: 0-CAP:SYM-CAP-0000 | L6: 0-CAP:FTP-CAP-0000 | M6: ~ | N6: FH | O6: 0402CG101J500NT | P6: C1546 | Q6: BASIC | R6: Preferred
A7: CAP-002-1203 | B7: =_xlfn.CONCAT("Cap ",G7," ",D7,"F ",F7," ",H7," ",J7,IF(C7," - BASIC","")) -> Cap Cer 12pF 50V C0G/NP0 0402 - BASIC | C7: =OR(AND(Q7=_enum!$AN$3,OR(R7=_enum!$AH$7,R7=_enum!$AH$3)),AND(V7=_enum!$AN$3,OR(W7=_enum!$AH$7,W7=_enum!$AH$3)),AND(AA7=_enum!$AN$3,OR(AB7=_enum!$AH$7,AB7=_enum!$AH$3)), AND(AF7=_enum!$AN$3,OR(AG7=_enum!$AH$7,AG7=_enum!$AH$3))) -> TRUE | D7: 12p | E7: {=IF(OR(D7="",D7="TBD"),"", _xlfn.LET( _xlpm.s,LOWER(TRIM(D7)), _xlpm.num,VALUE(LEFT(_xlpm.s,LEN(_xlpm.s)-1)), _xlpm.unit,RIGHT(_xlpm.s,1), _xlfn.SWITCH(_xlpm.unit, "p",_xlpm.num/1000, "n",_xlpm.num, "u",_xlpm.num*1000, D7) ))} -> 0.012 | F7: 50V | G7: Cer | H7: C0G/NP0 | I7: 5 | J7: 0402 | K7: 0-CAP:SYM-CAP-0000 | L7: 0-CAP:FTP-CAP-0000 | M7: ~ | N7: FH | O7: 0402CG120J500NT | P7: C1547 | Q7: BASIC | R7: Preferred
A8: CAP-002-1503 | B8: =_xlfn.CONCAT("Cap ",G8," ",D8,"F ",F8," ",H8," ",J8,IF(C8," - BASIC","")) -> Cap Cer 15pF 50V C0G/NP0 0402 - BASIC | C8: =OR(AND(Q8=_enum!$AN$3,OR(R8=_enum!$AH$7,R8=_enum!$AH$3)),AND(V8=_enum!$AN$3,OR(W8=_enum!$AH$7,W8=_enum!$AH$3)),AND(AA8=_enum!$AN$3,OR(AB8=_enum!$AH$7,AB8=_enum!$AH$3)), AND(AF8=_enum!$AN$3,OR(AG8=_enum!$AH$7,AG8=_enum!$AH$3))) -> TRUE | D8: 15p | E8: {=IF(OR(D8="",D8="TBD"),"", _xlfn.LET( _xlpm.s,LOWER(TRIM(D8)), _xlpm.num,VALUE(LEFT(_xlpm.s,LEN(_xlpm.s)-1)), _xlpm.unit,RIGHT(_xlpm.s,1), _xlfn.SWITCH(_xlpm.unit, "p",_xlpm.num/1000, "n",_xlpm.num, "u",_xlpm.num*1000, D8) ))} -> 0.015 | F8: 50V | G8: Cer | H8: C0G/NP0 | I8: 5 | J8: 0402 | K8: 0-CAP:SYM-CAP-0000 | L8: 0-CAP:FTP-CAP-0000 | M8: ~ | N8: FH | O8: 0402CG150J500NT | P8: C1548 | Q8: BASIC | R8: Preferred
A9: CAP-002-1803 | B9: =_xlfn.CONCAT("Cap ",G9," ",D9,"F ",F9," ",H9," ",J9,IF(C9," - BASIC","")) -> Cap Cer 18pF 50V C0G/NP0 0402 - BASIC | C9: =OR(AND(Q9=_enum!$AN$3,OR(R9=_enum!$AH$7,R9=_enum!$AH$3)),AND(V9=_enum!$AN$3,OR(W9=_enum!$AH$7,W9=_enum!$AH$3)),AND(AA9=_enum!$AN$3,OR(AB9=_enum!$AH$7,AB9=_enum!$AH$3)), AND(AF9=_enum!$AN$3,OR(AG9=_enum!$AH$7,AG9=_enum!$AH$3))) -> TRUE | D9: 18p | E9: {=IF(OR(D9="",D9="TBD"),"", _xlfn.LET( _xlpm.s,LOWER(TRIM(D9)), _xlpm.num,VALUE(LEFT(_xlpm.s,LEN(_xlpm.s)-1)), _xlpm.unit,RIGHT(_xlpm.s,1), _xlfn.SWITCH(_xlpm.unit, "p",_xlpm.num/1000, "n",_xlpm.num, "u",_xlpm.num*1000, D9) ))} -> 0.018 | F9: 50V | G9: Cer | H9: C0G/NP0 | I9: 5 | J9: 0402 | K9: 0-CAP:SYM-CAP-0000 | L9: 0-CAP:FTP-CAP-0000 | M9: ~ | N9: FH | O9: 0402CG180J500NT | P9: C1549 | Q9: BASIC | R9: Preferred
A10: CAP-002-2003 | B10: =_xlfn.CONCAT("Cap ",G10," ",D10,"F ",F10," ",H10," ",J10,IF(C10," - BASIC","")) -> Cap Cer 20pF 50V C0G/NP0 0402 - BASIC | C10: =OR(AND(Q10=_enum!$AN$3,OR(R10=_enum!$AH$7,R10=_enum!$AH$3)),AND(V10=_enum!$AN$3,OR(W10=_enum!$AH$7,W10=_enum!$AH$3)),AND(AA10=_enum!$AN$3,OR(AB10=_enum!$AH$7,AB10=_enum!$AH$3)), AND(AF10=_enum!$AN$3,OR(AG10=_enum!$AH$7,AG10=_enum!$AH$3))) -> TRUE | D10: 20p | E10: {=IF(OR(D10="",D10="TBD"),"", _xlfn.LET( _xlpm.s,LOWER(TRIM(D10)), _xlpm.num,VALUE(LEFT(_xlpm.s,LEN(_xlpm.s)-1)), _xlpm.unit,RIGHT(_xlpm.s,1), _xlfn.SWITCH(_xlpm.unit, "p",_xlpm.num/1000, "n",_xlpm.num, "u",_xlpm.num*1000, D10) ))} -> 0.02 | F10: 50V | G10: Cer | H10: C0G/NP0 | I10: 5 | J10: 0402 | K10: 0-CAP:SYM-CAP-0000 | L10: 0-CAP:FTP-CAP-0000 | M10: ~ | N10: FH | O10: 0402CG200J500NT | P10: C1554 | Q10: BASIC | R10: Preferred
A11: CAP-002-2203 | B11: =_xlfn.CONCAT("Cap ",G11," ",D11,"F ",F11," ",H11," ",J11,IF(C11," - BASIC","")) -> Cap Cer 22pF 50V C0G/NP0 0402 - BASIC | C11: =OR(AND(Q11=_enum!$AN$3,OR(R11=_enum!$AH$7,R11=_enum!$AH$3)),AND(V11=_enum!$AN$3,OR(W11=_enum!$AH$7,W11=_enum!$AH$3)),AND(AA11=_enum!$AN$3,OR(AB11=_enum!$AH$7,AB11=_enum!$AH$3)), AND(AF11=_enum!$AN$3,OR(AG11=_enum!$AH$7,AG11=_enum!$AH$3))) -> TRUE | D11: 22p | E11: {=IF(OR(D11="",D11="TBD"),"", _xlfn.LET( _xlpm.s,LOWER(TRIM(D11)), _xlpm.num,VALUE(LEFT(_xlpm.s,LEN(_xlpm.s)-1)), _xlpm.unit,RIGHT(_xlpm.s,1), _xlfn.SWITCH(_xlpm.unit, "p",_xlpm.num/1000, "n",_xlpm.num, "u",_xlpm.num*1000, D11) ))} -> 0.022 | F11: 50V | G11: Cer | H11: C0G/NP0 | I11: 5 | J11: 0402 | K11: 0-CAP:SYM-CAP-0000 | L11: 0-CAP:FTP-CAP-0000 | M11: ~ | N11: FH | O11: 0402CG220J500NT | P11: C1555 | Q11: BASIC | R11: Preferred
A12: CAP-002-2703 | B12: =_xlfn.CONCAT("Cap ",G12," ",D12,"F ",F12," ",H12," ",J12,IF(C12," - BASIC","")) -> Cap Cer 27pF 50V C0G/NP0 0402 - BASIC | C12: =OR(AND(Q12=_enum!$AN$3,OR(R12=_enum!$AH$7,R12=_enum!$AH$3)),AND(V12=_enum!$AN$3,OR(W12=_enum!$AH$7,W12=_enum!$AH$3)),AND(AA12=_enum!$AN$3,OR(AB12=_enum!$AH$7,AB12=_enum!$AH$3)), AND(AF12=_enum!$AN$3,OR(AG12=_enum!$AH$7,AG12=_enum!$AH$3))) -> TRUE | D12: 27p | E12: {=IF(OR(D12="",D12="TBD"),"", _xlfn.LET( _xlpm.s,LOWER(TRIM(D12)), _xlpm.num,VALUE(LEFT(_xlpm.s,LEN(_xlpm.s)-1)), _xlpm.unit,RIGHT(_xlpm.s,1), _xlfn.SWITCH(_xlpm.unit, "p",_xlpm.num/1000, "n",_xlpm.num, "u",_xlpm.num*1000, D12) ))} -> 0.027 | F12: 50V | G12: Cer | H12: C0G/NP0 | I12: 5 | J12: 0402 | K12: 0-CAP:SYM-CAP-0000 | L12: 0-CAP:FTP-CAP-0000 | M12: ~ | N12: FH | O12: 0402CG270J500NT | P12: C1557 | Q12: BASIC | R12: Preferred
A13: CAP-002-3303 | B13: =_xlfn.CONCAT("Cap ",G13," ",D13,"F ",F13," ",H13," ",J13,IF(C13," - BASIC","")) -> Cap Cer 33pF 50V C0G/NP0 0402 - BASIC | C13: =OR(AND(Q13=_enum!$AN$3,OR(R13=_enum!$AH$7,R13=_enum!$AH$3)),AND(V13=_enum!$AN$3,OR(W13=_enum!$AH$7,W13=_enum!$AH$3)),AND(AA13=_enum!$AN$3,OR(AB13=_enum!$AH$7,AB13=_enum!$AH$3)), AND(AF13=_enum!$AN$3,OR(AG13=_enum!$AH$7,AG13=_enum!$AH$3))) -> TRUE | D13: 33p | E13: {=IF(OR(D13="",D13="TBD"),"", _xlfn.LET( _xlpm.s,LOWER(TRIM(D13)), _xlpm.num,VALUE(LEFT(_xlpm.s,LEN(_xlpm.s)-1)), _xlpm.unit,RIGHT(_xlpm.s,1), _xlfn.SWITCH(_xlpm.unit, "p",_xlpm.num/1000, "n",_xlpm.num, "u",_xlpm.num*1000, D13) ))} -> 0.033 | F13: 50V | G13: Cer | H13: C0G/NP0 | I13: 5 | J13: 0402 | K13: 0-CAP:SYM-CAP-0000 | L13: 0-CAP:FTP-CAP-0000 | M13: ~ | N13: FH | O13: 0402CG330J500NT | P13: C1562 | Q13: BASIC | R13: Preferred
... A20: CAP-007-1061 | B20: =_xlfn.CONCAT("Cap ",G20," ",D20,"F ",F20," ",H20," ",J20,IF(C20," - BASIC","")) -> Cap Cer 10uF 25V X5R 0805 - BASIC | C20: =OR(AND(Q20=_enum!$AN$3,OR(R20=_enum!$AH$7,R20=_enum!$AH$3)),AND(V20=_enum!$AN$3,OR(W20=_enum!$AH$7,W20=_enum!$AH$3)),AND(AA20=_enum!$AN$3,OR(AB20=_enum!$AH$7,AB20=_enum!$AH$3)), AND(AF20=_enum!$AN$3,OR(AG20=_enum!$AH$7,AG20=_enum!$AH$3))) -> TRUE | D20: 10u | E20: {=IF(OR(D20="",D20="TBD"),"", _xlfn.LET( _xlpm.s,LOWER(TRIM(D20)), _xlpm.num,VALUE(LEFT(_xlpm.s,LEN(_xlpm.s)-1)), _xlpm.unit,RIGHT(_xlpm.s,1), _xlfn.SWITCH(_xlpm.unit, "p",_xlpm.num/1000, "n",_xlpm.num, "u",_xlpm.num*1000, D20) ))} -> 10000 | F20: 25V | G20: Cer | H20: X5R | I20: 10 | J20: 0805 | K20: 0-CAP:SYM-CAP-0000 | L20: 0-CAP:FTP-CAP-0002 | M20: ~ | N20: Samsung | O20: CL21A106KAYNNNE | P20: C15850 | Q20: BASIC | R20: Preferred
A21: CAP-008-2261 | B21: =_xlfn.CONCAT("Cap ",G21," ",D21,"F ",F21," ",H21," ",J21,IF(C21," - BASIC","")) -> Cap Cer 22uF 25V X5R 0805 | C21: =OR(AND(Q21=_enum!$AN$3,OR(R21=_enum!$AH$7,R21=_enum!$AH$3)),AND(V21=_enum!$AN$3,OR(W21=_enum!$AH$7,W21=_enum!$AH$3)),AND(AA21=_enum!$AN$3,OR(AB21=_enum!$AH$7,AB21=_enum!$AH$3)), AND(AF21=_enum!$AN$3,OR(AG21=_enum!$AH$7,AG21=_enum!$AH$3))) -> FALSE | D21: 22u | E21: {=IF(OR(D21="",D21="TBD"),"", _xlfn.LET( _xlpm.s,LOWER(TRIM(D21)), _xlpm.num,VALUE(LEFT(_xlpm.s,LEN(_xlpm.s)-1)), _xlpm.unit,RIGHT(_xlpm.s,1), _xlfn.SWITCH(_xlpm.unit, "p",_xlpm.num/1000, "n",_xlpm.num, "u",_xlpm.num*1000, D21) ))} -> 22000 | F21: 25V | G21: Cer | H21: X5R | I21: 20 | J21: 0805 | K21: 0-CAP:SYM-CAP-0000 | L21: 0-CAP:FTP-CAP-0002 | M21: ~ | N21: Samsung | O21: CL21A226MAQNNNE | P21: C45783 | Q21: BASIC | R21: EOL | AH21: 11/17/2025 - CL21A226MAQNNNE updated to EOL.
A22: CAP-009-4761 | B22: =_xlfn.CONCAT("Cap ",G22," ",D22,"F ",F22," ",H22," ",J22,IF(C22," - BASIC","")) -> Cap Cer 47uF 6.3V X5R 0805 - BASIC | C22: =OR(AND(Q22=_enum!$AN$3,OR(R22=_enum!$AH$7,R22=_enum!$AH$3)),AND(V22=_enum!$AN$3,OR(W22=_enum!$AH$7,W22=_enum!$AH$3)),AND(AA22=_enum!$AN$3,OR(AB22=_enum!$AH$7,AB22=_enum!$AH$3)), AND(AF22=_enum!$AN$3,OR(AG22=_enum!$AH$7,AG22=_enum!$AH$3))) -> TRUE | D22: 47u | E22: {=IF(OR(D22="",D22="TBD"),"", _xlfn.LET( _xlpm.s,LOWER(TRIM(D22)), _xlpm.num,VALUE(LEFT(_xlpm.s,LEN(_xlpm.s)-1)), _xlpm.unit,RIGHT(_xlpm.s,1), _xlfn.SWITCH(_xlpm.unit, "p",_xlpm.num/1000, "n",_xlpm.num, "u",_xlpm.num*1000, D22) ))} -> 47000 | F22: 6.3V | G22: Cer | H22: X5R | I22: 20 | J22: 0805 | K22: 0-CAP:SYM-CAP-0000 | L22: 0-CAP:FTP-CAP-0002 | M22: ~ | N22: Samsung | O22: CL21A476MQYNNNE | P22: C16780 | Q22: BASIC | R22: Preferred
A23: CAP-010-1061 | B23: =_xlfn.CONCAT("Cap ",G23," ",D23,"F ",F23," ",H23," ",J23,IF(C23," - BASIC","")) -> Cap Cer 10uF 50V X5R 0805 - BASIC | C23: =OR(AND(Q23=_enum!$AN$3,OR(R23=_enum!$AH$7,R23=_enum!$AH$3)),AND(V23=_enum!$AN$3,OR(W23=_enum!$AH$7,W23=_enum!$AH$3)),AND(AA23=_enum!$AN$3,OR(AB23=_enum!$AH$7,AB23=_enum!$AH$3)), AND(AF23=_enum!$AN$3,OR(AG23=_enum!$AH$7,AG23=_enum!$AH$3))) -> TRUE | D23: 10u | E23: {=IF(OR(D23="",D23="TBD"),"", _xlfn.LET( _xlpm.s,LOWER(TRIM(D23)), _xlpm.num,VALUE(LEFT(_xlpm.s,LEN(_xlpm.s)-1)), _xlpm.unit,RIGHT(_xlpm.s,1), _xlfn.SWITCH(_xlpm.unit, "p",_xlpm.num/1000, "n",_xlpm.num, "u",_xlpm.num*1000, D23) ))} -> 10000 | F23: 50V | G23: Cer | H23: X5R | I23: 10 | J23: 0805 | K23: 0-CAP:SYM-CAP-0000 | L23: 0-CAP:FTP-CAP-0002 | M23: ~ | N23: Murata | O23: GRM21BR61H106KE43L | P23: C440198 | Q23: BASIC | R23: Preferred
A24: CAP-010-2251 | B24: =_xlfn.CONCAT("Cap ",G24," ",D24,"F ",F24," ",H24," ",J24,IF(C24," - BASIC","")) -> Cap Cer 2.2uF 50V X5R 0805 - BASIC | C24: =OR(AND(Q24=_enum!$AN$3,OR(R24=_enum!$AH$7,R24=_enum!$AH$3)),AND(V24=_enum!$AN$3,OR(W24=_enum!$AH$7,W24=_enum!$AH$3)),AND(AA24=_enum!$AN$3,OR(AB24=_enum!$AH$7,AB24=_enum!$AH$3)), AND(AF24=_enum!$AN$3,OR(AG24=_enum!$AH$7,AG24=_enum!$AH$3))) -> TRUE | D24: 2.2u | E24: {=IF(OR(D24="",D24="TBD"),"", _xlfn.LET( _xlpm.s,LOWER(TRIM(D24)), _xlpm.num,VALUE(LEFT(_xlpm.s,LEN(_xlpm.s)-1)), _xlpm.unit,RIGHT(_xlpm.s,1), _xlfn.SWITCH(_xlpm.unit, "p",_xlpm.num/1000, "n",_xlpm.num, "u",_xlpm.num*1000, D24) ))} -> 2200 | F24: 50V | G24: Cer | H24: X5R | I24: 10 | J24: 0805 | K24: 0-CAP:SYM-CAP-0000 | L24: 0-CAP:FTP-CAP-0002 | M24: ~ | N24: Samsung | O24: CL21A225KBQNNNE | P24: C377773 | Q24: BASIC | R24: Preferred
A25: CAP-999-0000 | B25: PLACEHOLDER - 0402 | C25: =OR(AND(Q25=_enum!$AN$3,OR(R25=_enum!$AH$7,R25=_enum!$AH$3)),AND(V25=_enum!$AN$3,OR(W25=_enum!$AH$7,W25=_enum!$AH$3)),AND(AA25=_enum!$AN$3,OR(AB25=_enum!$AH$7,AB25=_enum!$AH$3)), AND(AF25=_enum!$AN$3,OR(AG25=_enum!$AH$7,AG25=_enum!$AH$3))) -> FALSE | D25: TBD | E25: TBD | F25: TBD | G25: Cer | H25: N/A | I25: ~ | J25: 0402 | K25: 0-CAP:SYM-CAP-0000 | L25: 0-CAP:FTP-CAP-0000 | M25: ~
A26: CAP-999-0001 | B26: PLACEHOLDER - 0603 | C26: =OR(AND(Q26=_enum!$AN$3,OR(R26=_enum!$AH$7,R26=_enum!$AH$3)),AND(V26=_enum!$AN$3,OR(W26=_enum!$AH$7,W26=_enum!$AH$3)),AND(AA26=_enum!$AN$3,OR(AB26=_enum!$AH$7,AB26=_enum!$AH$3)), AND(AF26=_enum!$AN$3,OR(AG26=_enum!$AH$7,AG26=_enum!$AH$3))) -> FALSE | D26: TBD | E26: TBD | F26: TBD | G26: Cer | H26: N/A | I26: ~ | J26: 0603 | K26: 0-CAP:SYM-CAP-0000 | L26: 0-CAP:FTP-CAP-0001 | M26: ~
A27: CAP-999-0002 | B27: PLACEHOLDER - 0805 | C27: =OR(AND(Q27=_enum!$AN$3,OR(R27=_enum!$AH$7,R27=_enum!$AH$3)),AND(V27=_enum!$AN$3,OR(W27=_enum!$AH$7,W27=_enum!$AH$3)),AND(AA27=_enum!$AN$3,OR(AB27=_enum!$AH$7,AB27=_enum!$AH$3)), AND(AF27=_enum!$AN$3,OR(AG27=_enum!$AH$7,AG27=_enum!$AH$3))) -> FALSE | D27: TBD | E27: TBD | F27: TBD | G27: Cer | H27: N/A | I27: ~ | J27: 0805 | K27: 0-CAP:SYM-CAP-0000 | L27: 0-CAP:FTP-CAP-0002 | M27: ~

Sheet CNT
A1: IPN | B1: Description | C1: Value | D1: Symbols | E1: Footprints | F1: Datasheet | G1: MFN_1 | H1: MPN_1 | I1: LCSC_1 | J1: LCSC_TYPE_1 | K1: Status_1 | L1: MFN_2 | M1: MPN_2 | N1: LCSC_2 | O1: LCSC_TYPE_2 | P1: Status_2 | Q1: MFN_3 | R1: MPN_3 | S1: LCSC_3 | T1: LCSC_TYPE_3 | U1: Status_3 | V1: MFN_4 | W1: MPN_4 | X1: LCSC_4 | Y1: LCSC_TYPE_4 | Z1: Status_4 | AA1: Comment
A2: CNT-112-0000 | B2: 1x02 Pin, Male Socket, Horz, 5.08mm | C2: CNT1120000 | D2: 0-CNT:SYM-CNT-0012 | E2: 0-CNT:FTP-CNT-0000 | F2: https://www.phoenixcontact.com/en-us/products/pcb-header-mstba-25-hc-2-g-508-1923869?type=pdf | G2: Phoenix Contact | H2: 1923869 | I2: C5443585, EXT | K2: Preferred
A3: CNT-113-0000 | B3: 1x03 Pin, Male Socket, Horz, 5.08mm | C3: CNT1130000 | D3: 0-CNT:SYM-CNT-0011 | E3: 0-CNT:FTP-CNT-0001 | F3: https://www.phoenixcontact.com/en-ca/products/pcb-header-mstba-25-hc-3-g-508-1923872 | G3: Phoenix Contact | H3: 1923872 | I3: C5484355, EXT | K3: Preferred
A4: CNT-114-0000 | B4: 1x04 Pin, Male Socket, Horz, 5.08mm | C4: CNT1140000 | D4: 0-CNT:SYM-CNT-0010 | E4: 0-CNT:FTP-CNT-0002 | F4: https://www.phoenixcontact.com/en-pc/products/pcb-header-mstba-25-hc-4-g-508-1923885 | G4: Phoenix Contact | H4: 1923885 | I4: C6983854, EXT | K4: Preferred
A5: CNT-122-0000 | B5: 1x02 Pin, Male Header, Vert, 2.54mm | C5: CNT1220000 | D5: 0-CNT:SYM-CNT-0001 | E5: 0-CNT:FTP-CNT-0007 | G5: Molex | H5: 22284020 | I5: C234182, EXT | K5: Alternate
A6: CNT-123-0000 | B6: 1x03 Pin, Male Header, Vert, 2.54mm | C6: CNT1230000 | D6: 0-CNT:SYM-CNT-0002 | E6: 0-CNT:FTP-CNT-0008 | G6: Molex | H6: 22284030 | I6: C587036, EXT | K6: Alternate
A7: CNT-125-0000 | B7: 1x05 Pin, Male Header, Vert, 2.54mm | C7: CNT1250000 | D7: 0-CNT:SYM-CNT-0003 | E7: 0-CNT:FTP-CNT-0010 | G7: Molex | H7: 22284050 | I7: C563741, EXT | K7: Alternate
A8: CNT-141-0000 | B8: 1 Pin, Drill 1mm, No Component Object | C8: CNT1410000 | D8: 0-CNT:SYM-CNT-0013 | E8: 0-CNT:FTP-CNT-0012 | F8: n/a | G8: n/a | H8: n/a | I8: n/a | K8: Preferred

Sheet CPD
A1: IPN | B1: Auto-Gen Description | C1: Description | D1: Value | E1: Case/Package Size | F1: Type | G1: Symbols | H1: Footprints | I1: Datasheet | J1: MFN_1 | K1: MPN_1 | L1: LCSC_1 | M1: LCSC_TYPE_1 | N1: Status_1 | O1: MFN_2 | P1: MPN_2 | Q1: LCSC_2 | R1: LCSC_TYPE_2 | S1: Status_2 | T1: MFN_3 | U1: MPN_3 | V1: LCSC_3 | W1: LCSC_TYPE_3 | X1: Status_3 | Y1: MFN_4 | Z1: MPN_4 | AA1: LCSC_4 | AB1: LCSC_TYPE_4 | AC1: Status_4 | AD1: Comment

Sheet DIO
A1: IPN | B1: Description | C1: Value | D1: Vfd @10mA [V] | E1: DC Current [A] | F1: Reverse Voltage [V] | G1: Power Dissipation [W] | H1: Case/Package Size | I1: Type | J1: Other... | K1: Symbols | L1: Footprints | M1: Datasheet | N1: MFN_1 | O1: MPN_1 | P1: LCSC_1 | Q1: LCSC_TYPE_1 | R1: Status_1 | S1: MFN_2 | T1: MPN_2 | U1: LCSC_2 | V1: LCSC_TYPE_2 | W1: Status_2 | X1: MFN_3 | Y1: MPN_3 | Z1: LCSC_3 | AA1: LCSC_TYPE_3 | AB1: Status_3 | AC1: MFN_4 | AD1: MPN_4 | AE1: LCSC_4 | AF1: LCSC_TYPE_4 | AG1: Status_4 | AH1: Comment
A2: DIO-021-0000 | B2: DIO Standard 100VR SOT23-3 - BASIC | C2: DIO0210000 | D2: 0.855 | E2: 0.125 | F2: 100 | G2: 0.25 | H2: SOT23-3 | I2: Standard | K2: 0-DIO:SYM-DIO-0005 | L2: 1-PACKAGES:Generic-SOT-23-3 | M2: ~ | N2: Nexperia | O2: BAV99,215 | P2: C2500, BASIC | R2: Preferred
A3: DIO-021-0001 | B3: DIO Standard 100.0VR SOD-323 - BASIC | C3: DIO0210001 | D3: 0.855 | E3: 0.15 | F3: 100 | G3: 0.2 | H3: SOD-323 | I3: Standard | K3: 0-DIO:SYM-DIO-0004 | L3: 0-DIO:FTP-DIO-0003 | M3: ~ | N3: JCST | O3: 1N4148WS | P3: C2128, BASIC | R3: Preferred
A4: DIO-099-9999 | B4: TBD | C4: DIO0999999 | D4: ~ | E4: ~ | F4: ~ | G4: ~ | H4: ~ | I4: Standard | J4: ~ | K4: 0-DIO:SYM-DIO-0004 | L4: ~ | M4: ~ | N4: ~ | O4: ~ | P4: ~ | R4: Banned
A5: DIO-311-0000 | B5: DIO TVS 3.3VRWM SOD-523 | C5: DIO3110000 | D5: ~ | E5: ~ | F5: 3.3 | G5: ~ | H5: SOD-523 | I5: TVS | J5: Vrwm=3.3V, Vbr=7.0V, Vhold=1.15V, Ihold=20mA, IPP=5A@8/20us, IEC61000-4-2 15kV (air & contact) | K5: 0-DIO:SYM-DIO-0001 | L5: 0-DIO:FTP-DIO-0002 | M5: ~ | N5: Onsemi | O5: ESD8351XV2T_G | P5: C233437, EXT | R5: Preferred | AH5: 07/12/2025: Beware risk of latchup due to crowbar response.
A6: DIO-321-0000 | B6: DIO TVS 5.0VRWM SOD-123W | C6: DIO3210000 | D6: ~ | E6: ~ | F6: 5 | G6: 200PP | H6: SOD-123W | I6: TVS | J6: Vrwm=5.0V, Vbr=7.0V, IR=800uA | K6: 0-DIO:SYM-DIO-0001 | L6: 0-DIO:FTP-DIO-0004 | M6: ~ | N6: Nexperia | O6: PTVS5V0S1UR,115 | P6: C478011, EXT | R6: Preferred | S6: Taiwan Semiconductor | T6: SMF5.0A | V6: n/a | W6: Alternate
A7: DIO-321-0001 | B7: DIO TVS 5.0VR SOD-323 | C7: DIO3210001 | D7: ~ | E7: ~ | F7: 5 | G7: 350PP | H7: SOD-323 | I7: TVS | J7: Vrwm=5.0V, Vbr=xxV, IR=10uA | K7: 0-DIO:SYM-DIO-0001 | L7: 0-DIO:FTP-DIO-0003 | M7: ~ | N7: Bourns | O7: CDSOD323-T05S | P7: C3699212, EXT | R7: Preferred | S7: Onsemi | T7: SD05T3G | V7: C896890 | W7: Candidate
A8: DIO-361-0000 | B8: DIO BI-TVS 26.0VR DO-214AC | C8: DIO3610000 | D8: ~ | E8: ~ | F8: 26 | G8: 400PP | H8: DO-214AC | I8: TVS | J8: Bidirectional, Vrwm=28V, Vbr=28.9V @32mA, Vhold=1.15V, IPP=9.5A, 42.1V @8/20us | K8: 0-DIO:SYM-DIO-0002 | L8: 0-DIO:FTP-DIO-0005 | M8: https://www.littelfuse.com/assetdocs/tvs-diodes-smaj-datasheet?assetguid=13c2a823-03b8-4d1f-9ddc-9b44670aed9d | N8: Littlefuse | O8: SMAJ26CA* | P8: C148228, EXT | R8: Preferred
A9: DIO-401-0000 | B9: DIO LED 5.0VR 0603 WHT - BASIC | C9: WHT | D9: 2.9 | E9: 0.03 | F9: 5 | G9: 0.1 | H9: 0603 | I9: LED | J9: Color=WHT | K9: 0-DIO:SYM-DIO-0000 | L9: 0-DIO:FTP-DIO-0000 | M9: ~ | N9: Hubei | O9: KT-0603W | P9: C2290, BASIC | R9: Preferred
A10: DIO-401-0001 | B10: DIO LED 5.0VR 0805 WHT - BASIC | C10: WHT | D10: 2.9 | E10: 0.025 | F10: 5 | G10: 0.08 | H10: 0805 | I10: LED | J10: Color=WHT | K10: 0-DIO:SYM-DIO-0000 | L10: 0-DIO:FTP-DIO-0001 | M10: ~ | N10: Hubei | O10: KT-0805W | P10: C34499, BASIC | R10: Preferred
A11: DIO-411-0000 | B11: DIO LED 5.0VR 0603 RED - BASIC | C11: RED | D11: 1.9 | E11: 0.025 | F11: 5 | G11: 0.04 | H11: 0603 | I11: LED | J11: λ=620nm, Color=RED | K11: 0-DIO:SYM-DIO-0000 | L11: 0-DIO:FTP-DIO-0000 | M11: ~ | N11: Hubei | O11: KT-0603R | P11: C2286, BASIC | R11: Preferred
A12: DIO-421-0001 | B12: DIO LED 5.0VR 0805 GRN - BASIC | C12: GRN | D12: 2 | E12: 0.02 | F12: 5 | G12: 0.04 | H12: 0805 | I12: LED | J12: λ=520nm, Color=GRN | K12: 0-DIO:SYM-DIO-0000 | L12: 0-DIO:FTP-DIO-0001 | M12: ~ | N12: Hubei | O12: KT-0805G | P12: C2297, BASIC | R12: Preferred
A13: DIO-431-0000 | B13: DIO LED 5.0VR 0603 BLU | C13: BLU | D13: 3 | E13: 0.025 | F13: 5 | G13: 0.075 | H13: 0603 | I13: LED | J13: λ=470nm, Color=BLU | K13: 0-DIO:SYM-DIO-0000 | L13: 0-DIO:FTP-DIO-0000 | M13: ~ | N13: Hubei | O13: KT-0603B | P13: C2288, EXT | R13: Preferred
A14: DIO-441-0000 | B14: DIO LED 5.0VR 0603 YLW | C14: YLW | D14: 2 | E14: 0.025 | F14: 5 | G14: 0.04 | H14: 0603 | I14: LED | J14: λ=590nm, Color=YLW | K14: 0-DIO:SYM-DIO-0000 | L14: 0-DIO:FTP-DIO-0000 | M14: ~ | N14: Hubei | O14: KT-0603Y | P14: C2287, EXT | R14: Preferred
A15: DIO-441-0001 | B15: DIO LED 5.0VR 0805 YLW - BASIC | C15: YLW | D15: 2 | E15: 0.02 | F15: 5 | G15: 0.04 | H15: 0805 | I15: LED | J15: λ=590nm, Color=YLW | K15: 0-DIO:SYM-DIO-0000 | L15: 0-DIO:FTP-DIO-0001 | M15: ~ | N15: Hubei | O15: KT-0805Y | P15: C2296, BASIC | R15: Preferred

Sheet FAB
A1: IPN | B1: Description | C1: Value | D1: Symbols | E1: Footprints | F1: Datasheet | G1: MFN_1 | H1: MPN_1 | I1: LCSC_1 | J1: LCSC_TYPE_1 | K1: Status_1 | L1: MFN_2 | M1: MPN_2 | N1: LCSC_2 | O1: LCSC_TYPE_2 | P1: Status_2 | Q1: MFN_3 | R1: MPN_3 | S1: LCSC_3 | T1: LCSC_TYPE_3 | U1: Status_3 | V1: MFN_4 | W1: MPN_4 | X1: LCSC_4 | Y1: LCSC_TYPE_4 | Z1: Status_4 | AA1: Comment
A2: FAB-000-0000 | B2: SMD Solder Jumper, 0.5x1.7mm, 0.2mm gap, Open | C2: FAB0000000 | D2: 0-FAB:SYM-FAB-0000 | E2: 0-FAB:FTP-FAB-0000 | F2: ~ | G2: ~ | H2: ~ | I2: ~ | K2: Preferred
A3: FAB-100-0000 | B3: Fiducial. 1mm CU, 2mm SM, JLC | C3: FAB0030000 | D3: 0-FAB:SYM-FAB-0005 | E3: 0-FAB:FTP-FAB-0005 | F3: ~ | G3: ~ | H3: ~ | I3: ~ | K3: Preferred
A4: FAB-200-0000 | B4: Tooling Hole, 1.152mm NPTH, JLCPCB | C4: FAB0020000 | D4: 0-FAB:SYM-FAB-0004 | E4: 0-FAB:FTP-FAB-0004 | F4: ~ | G4: ~ | H4: ~ | I4: ~ | K4: Preferred
A5: FAB-400-0000 | B5: Oscilloscope Probe, Test Point, w/ Ground, 5mm | C5: FAB4000000 | D5: 0-FAB:SYM-FAB-0001 | E5: 0-FAB:FTP-FAB-0001 | F5: ~ | G5: ~ | H5: ~ | I5: ~ | K5: Preferred
A6: FAB-400-0001 | B6: Oscilloscope Probe, Test Point, w/ Ground, 3mm | C6: FAB4000001 | D6: 0-FAB:SYM-FAB-0001 | E6: 0-FAB:FTP-FAB-0002 | F6: ~ | G6: ~ | H6: ~ | I6: ~ | K6: Preferred
A7: FAB-400-0002 | B7: Probe, Test Point, Keystone 5001 - Black | C7: FAB4000002 | D7: 0-FAB:SYM-FAB-0003 | E7: 0-FAB:FTP-FAB-0003a | F7: ~ | G7: Ronghe | H7: RH-5001 | I7: C5199801, EXT | K7: Preferred | L7: Keystone | M7: 5001 | O7: C238122, EXT | P7: Alternate
A8: FAB-400-0003 | B8: Probe, Test Point, Keystone 5000 - Red | C8: FAB4000003 | D8: 0-FAB:SYM-FAB-0003 | E8: 0-FAB:FTP-FAB-0003b | F8: ~ | G8: Ronghe | H8: RH-5000 | I8: C5277086, EXT | K8: Preferred | L8: Keystone | M8: 5000 | O8: C5277086, EXT | P8: Alternate

Sheet ICS
A1: IPN | B1: Auto-Gen Description | C1: Description | D1: Value | E1: Case/Package Size | F1: Type | G1: Symbols | H1: Footprints | I1: Datasheet | J1: MFN_1 | K1: MPN_1 | L1: LCSC_1 | M1: LCSC_TYPE_1 | N1: Status_1 | O1: MFN_2 | P1: MPN_2 | Q1: LCSC_2 | R1: LCSC_TYPE_2 | S1: Status_2 | T1: MFN_3 | U1: MPN_3 | V1: LCSC_3 | W1: LCSC_TYPE_3 | X1: Status_3 | Y1: MFN_4 | Z1: MPN_4 | AA1: LCSC_4 | AB1: LCSC_TYPE_4 | AC1: Status_4 | AD1: Comment
A2: ICS-000-0000 | C2: Quad Tri-State Buffer, 2.5ns RT, TSSOP-14 | D2: ICS0000000 | E2: TSSOP-14 (4.40mm) | F2: Tri-State Buffer | G2: 0-ICS:SYM-ICS-0000 | H2: 1-PACKAGES:Generic-TSSOP-14_4.4x5mm_P0.65mm | I2: https://assets.nexperia.com/documents/data-sheet/74LVC125A.pdf | J2: Nexperia | K2: 74LVC125APW,118 | L2: C6059, EXT | N2: Preferred
A3: ICS-000-0001 | C3: Single Tri-State Buffer, 3ns RT, TSSOP-5 | D3: ICS0000001 | E3: SOT-353 | F3: Tri-State Buffer | G3: 0-ICS:SYM-ICS-0001 | H3: 1-PACKAGES:Generic-SOT-353_SC-70-5 | I3: https://assets.nexperia.com/documents/data-sheet/74LVC1G125.pdf | J3: Nexperia | K3: 74LVC1G125GW,125 | L3: C12519, EXT | N3: Preferred
A4: ICS-001-0000 | C4: Quad Nand Gate, 2 Input, 2.5ns RT, SOIC-14 | D4: ICS0010000 | E4: SOIC-14 (3.90mm) | F4: Logic, NAND | G4: 0-ICS:SYM-ICS-0002 | H4: 1-PACKAGES:Generic-SOIC-14_3.9x8.7mm_P1.27mm | I4: https://assets.nexperia.com/documents/data-sheet/74ALVC00.pdf | J4: Nexperia | K4: 74ALVC00D,118 | L4: N/A | N4: Preferred
A5: ICS-002-0000 | C5: Logic Level Translator | D5: ICS0020000 | E5: TSSOP-24 (4.40mm) | F5: Logic Level Translator | G5: 0-ICS:SYM-ICS-0003 | H5: 1-PACKAGES:Generic-TSSOP-24_4.4x7.8mm_P0.65mm.kicad_mod | I5: https://assets.nexperia.com/documents/data-sheet/74LVC4245A.pdf | J5: Nexperia | K5: 74LVC4245APW,118 | L5: C6091, EXT | N5: Preferred

Sheet IND
A1: IPN | B1: Description | C1: Value | D1: Imax [A] | E1: DCR [mΩ] | F1: Case/Package Size | G1: Type | H1: Symbols | I1: Footprints | J1: Datasheet | K1: MFN_1 | L1: MPN_1 | M1: LCSC_1 | N1: LCSC_TYPE_1 | O1: Status_1 | P1: MFN_2 | Q1: MPN_2 | R1: LCSC_2 | S1: LCSC_TYPE_2 | T1: Status_2 | U1: MFN_3 | V1: MPN_3 | W1: LCSC_3 | X1: LCSC_TYPE_3 | Y1: Status_3 | Z1: MFN_4 | AA1: MPN_4 | AB1: LCSC_4 | AC1: LCSC_TYPE_4 | AD1: Status_4 | AE1: Comment
A2: IND-000-2204 | B2: Ind, Power 22uH 0.76A 350mΩ 4.0x4.0 | C2: 22u | D2: 0.76 | E2: 350 | F2: 4.0x4.0 | G2: Ind, Power | H2: 0-IND:SYM-IND-0001 | I2: 0-IND:FTP-IND-0000 | J2: https://mm.digikey.com/Volume0/opasdata/d220001/medias/docus/610/NRS4018T220MDGJ_SS.pdf | K2: Taiyo Yuden | L2: NRS4018T220MDGJ | M2: C222884, EXT | O2: Preferred | P2: Pulse Electronics | Q2: BWVS00404018220M00 | S2: N/A | T2: Candidate
A3: IND-001-4703 | B3: Ind, Power 4.7uH 1.2A 160mΩ 3.0x3.0 | C3: 4.7u | D3: 1.2 | E3: 160 | F3: 3.0x3.0 | G3: Ind, Power | H3: 0-IND:SYM-IND-0001 | I3: 0-IND:FTP-IND-0001 | J3: https://mm.digikey.com/Volume0/opasdata/d220001/medias/docus/610/NRH3012T4R7MN_SS.pdf | K3: Taiyo Yuden | L3: NRH3012T4R7MN | M3: C92955, EXT | O3: Preferred | P3: TDK | Q3: VLS3012CX-4R7M-1 | S3: C2047716, EXT | T3: Candidate

Sheet MCU
A1: IPN | B1: Description | C1: Value | D1: Case/Package Size | E1: Symbols | F1: Footprints | G1: Datasheet | H1: MFN_1 | I1: MPN_1 | J1: LCSC_1 | K1: LCSC_TYPE_1 | L1: Status_1 | M1: MFN_2 | N1: MPN_2 | O1: LCSC_2 | P1: LCSC_TYPE_2 | Q1: Status_2 | R1: MFN_3 | S1: MPN_3 | T1: LCSC_3 | U1: LCSC_TYPE_3 | V1: Status_3 | W1: MFN_4 | X1: MPN_4 | Y1: LCSC_4 | Z1: LCSC_TYPE_4 | AA1: Status_4 | AB1: Comment
A2: MCU-000-0000 | B2: ATTINY1616 - 20MHz, 16kB Flash, 2kB SRAM, 256B EEPROM, VQFN-20 | C2: ATTINY1616-MN_ | D2: VQFN-24 | E2: 0-MCU:SYM-MCU-0000 | F2: 1-PACKAGES:Generic-VQFN-20-1EP_3x3mm_P0.4mm_EP1.7x1.7mm | G2: https://ww1.microchip.com/downloads/en/DeviceDoc/ATtiny1614-16-17-DataSheet-DS40002204A.pdf | H2: Microchip | I2: ATtiny1617-MN_ | J2: C507118, EXT | L2: Preferred

Sheet MEC
A1: IPN | B1: Auto-Gen Description | C1: Description | D1: Value | E1: Case/Package Size | F1: Type | G1: Symbols | H1: Footprints | I1: Datasheet | J1: MFN_1 | K1: MPN_1 | L1: LCSC_1 | M1: LCSC_TYPE_1 | N1: Status_1 | O1: MFN_2 | P1: MPN_2 | Q1: LCSC_2 | R1: LCSC_TYPE_2 | S1: Status_2 | T1: MFN_3 | U1: MPN_3 | V1: LCSC_3 | W1: LCSC_TYPE_3 | X1: Status_3 | Y1: MFN_4 | Z1: MPN_4 | AA1: LCSC_4 | AB1: LCSC_TYPE_4 | AC1: Status_4 | AD1: Comment

Sheet MRK
A1: IPN | B1: Auto-Gen Description | C1: Description | D1: Value | E1: Case/Package Size | F1: Type | G1: Symbols | H1: Footprints | I1: Datasheet | J1: MFN_1 | K1: MPN_1 | L1: LCSC_1 | M1: LCSC_TYPE_1 | N1: Status_1 | O1: MFN_2 | P1: MPN_2 | Q1: LCSC_2 | R1: LCSC_TYPE_2 | S1: Status_2 | T1: MFN_3 | U1: MPN_3 | V1: LCSC_3 | W1: LCSC_TYPE_3 | X1: Status_3 | Y1: MFN_4 | Z1: MPN_4 | AA1: LCSC_4 | AB1: LCSC_TYPE_4 | AC1: Status_4 | AD1: Comment
A2: MRK-000-0000 | C2: Shamrock Circuits Logo - Medium | D2: ~ | E2: ~ | F2: ~ | G2: 0-MRK:SYM-MRK-0000 | H2: 0-MRK:FTP-MRK-0000 | I2: ~ | J2: ~ | K2: ~ | L2: ~ | N2: Preferred
A3: MRK-000-0001 | C3: Shamrock Circuits Logo - Small | D3: ~ | E3: ~ | F3: ~ | G3: 0-MRK:SYM-MRK-0000 | H3: 0-MRK:FTP-MRK-0001 | I3: ~ | J3: ~ | K3: ~ | L3: ~ | N3: Preferred
A4: MRK-001-0000 | C4: JLCJLCJLC | D4: ~ | E4: ~ | F4: ~ | G4: 0-MRK:SYM-MRK-0002 | H4: 0-MRK:FTP-MRK-0003 | I4: ~ | J4: ~ | K4: ~ | L4: ~ | N4: Preferred
A5: MRK-002-0000 | C5: Serial Number - Small | D5: ~ | E5: ~ | F5: ~ | G5: 0-MRK:SYM-MRK-0001 | H5: 0-MRK:FTP-MRK-0002b | I5: ~ | J5: ~ | K5: ~ | L5: ~ | N5: Preferred
A6: MRK-002-0001 | C6: Serial Number - Medium | D6: ~ | E6: ~ | F6: ~ | G6: 0-MRK:SYM-MRK-0001 | H6: 0-MRK:FTP-MRK-0002a | I6: ~ | J6: ~ | K6: ~ | L6: ~ | N6: Preferred
A7: MRK-003-0000 | C7: Quality Check - Small | D7: ~ | E7: ~ | F7: ~ | G7: 0-MRK:SYM-MRK-0003 | H7: 0-MRK:FTP-MRK-0004a | I7: ~ | J7: ~ | K7: ~ | L7: ~ | N7: Preferred
A8: MRK-003-0001 | C8: Quality Check - Medium | D8: ~ | E8: ~ | F8: ~ | G8: 0-MRK:SYM-MRK-0003 | H8: 0-MRK:FTP-MRK-0004b | I8: ~ | J8: ~ | K8: ~ | L8: ~ | N8: Preferred

Sheet OPT
A1: IPN | B1: Auto-Gen Description | C1: Description | D1: Value | E1: Case/Package Size | F1: Type | G1: Symbols | H1: Footprints | I1: Datasheet | J1: MFN_1 | K1: MPN_1 | L1: LCSC_1 | M1: LCSC_TYPE_1 | N1: Status_1 | O1: MFN_2 | P1: MPN_2 | Q1: LCSC_2 | R1: LCSC_TYPE_2 | S1: Status_2 | T1: MFN_3 | U1: MPN_3 | V1: LCSC_3 | W1: LCSC_TYPE_3 | X1: Status_3 | Y1: MFN_4 | Z1: MPN_4 | AA1: LCSC_4 | AB1: LCSC_TYPE_4 | AC1: Status_4 | AD1: Comment

Sheet OSC
A1: IPN | B1: Auto-Gen Description | C1: Description | D1: Value | E1: Case/Package Size | F1: Type | G1: Symbols | H1: Footprints | I1: Datasheet | J1: MFN_1 | K1: MPN_1 | L1: LCSC_1 | M1: LCSC_TYPE_1 | N1: Status_1 | O1: MFN_2 | P1: MPN_2 | Q1: LCSC_2 | R1: LCSC_TYPE_2 | S1: Status_2 | T1: MFN_3 | U1: MPN_3 | V1: LCSC_3 | W1: LCSC_TYPE_3 | X1: Status_3 | Y1: MFN_4 | Z1: MPN_4 | AA1: LCSC_4 | AB1: LCSC_TYPE_4 | AC1: Status_4 | AD1: Comment

Sheet REG
A1: IPN | B1: Auto-Gen Description | C1: Description | D1: Value | E1: Type | F1: Case/Package Size | G1: Other... | H1: Symbols | I1: Footprints | J1: Datasheet | K1: MFN_1 | L1: MPN_1 | M1: LCSC_1 | N1: LCSC_TYPE_1 | O1: Status_1 | P1: MFN_2 | Q1: MPN_2 | R1: LCSC_2 | S1: LCSC_TYPE_2 | T1: Status_2 | U1: MFN_3 | V1: MPN_3 | W1: LCSC_3 | X1: LCSC_TYPE_3 | Y1: Status_3 | Z1: MFN_4 | AA1: MPN_4 | AB1: LCSC_4 | AC1: LCSC_TYPE_4 | AD1: Status_4 | AE1: Comment
A2: REG-121-0000 | C2: Boost type Adjustable 3.3V~28V 1.8V~5.5V SOT-23-6 DC-DC | D2: REG1210000 | E2: BOOST | F2: SOT23-6 | H2: 0-REG:SYM-REG-0000 | I2: 1-PACKAGES:Generic-SOT23-6 | J2: https://www.ti.com/lit/ds/symlink/tlv61046a.pdf?ts=1752317963415&ref_url=https%253A%252F%252Fwww.ti.com%252Fproduct%252FTLV61046A | K2: Texas Instruments | L2: TLV61046ADBV* | M2: C464815, BASIC | O2: Preferred | P2: Analog Devices | Q2: LT3461 | S2: ??? | T2: Candidate | U2: Analog Devices | W2: LTC3400 | X2: ??? | Y2: Candidate
A3: REG-991-0000 | C3: Boost Converter with Battery Management for Energy Harvester (Solar) | D3: BQ25504RG | E3: ENERGY HARVEST | F3: VQFN-16 | G3: Vin_min=0.6V, Vin_max=3V, Vbat_min=2.5V, Vbat_max=5.25V | H3: 0-REG:SYM-REG-0001 | I3: 1-PACKAGES:Generic-VQFN-16-1EP_3x3mm_P0.5mm_EP1.68x1.68mm | J3: https://www.ti.com/lit/ds/symlink/bq25504.pdf?ts=1752276394083 | K3: Texas Instruments | L3: BQ25504RGT* | M3: C2876746, BASIC | O3: Preferred

Sheet RES
A1: IPN | B1: Description | C1: Value | D1: Power Rating [W] | E1: Type | F1: TCR [ppm/K] | G1: Tolerance [%] | H1: Case/Package Size | I1: Symbols | J1: Footprints | K1: Datasheet | L1: MFN_1 | M1: MPN_1 | N1: LCSC_1 | O1: LCSC_TYPE_1 | P1: Status_1 | Q1: MFN_2 | R1: MPN_2 | S1: LCSC_2 | T1: LCSC_TYPE_2 | U1: Status_2 | V1: MFN_3 | W1: MPN_3 | X1: LCSC_3 | Y1: LCSC_TYPE_3 | Z1: Status_3 | AA1: MFN_4 | AB1: MPN_4 | AC1: LCSC_4 | AD1: LCSC_TYPE_4 | AE1: Status_4 | AF1: Comment
A2: RES-000-0000 | B2: RES ThickF 0Ω ±1% 0.1W 0603 - BASIC | C2: 0 | D2: 0.1 | E2: ThickF | F2: 200 | G2: 1 | H2: 0603 | I2: 0-RES:SYM-RES-0000 | J2: 0-RES:FTP-RES-0001 | K2: ~ | L2: UNI-ROYAL | M2: 0603WAF0000T5E | N2: C21189, BASIC | P2: Preferred | AF2: 07/08/2025: Tolerance spec is placeholder, MPN_1 is poorly documented.
A3: RES-000-1000 | B3: RES ThickF 1Ω ±1% 0.1W 0603 - BASIC | C3: 1 | D3: 0.1 | E3: ThickF | F3: 200 | G3: 1 | H3: 0603 | I3: 0-RES:SYM-RES-0000 | J3: 0-RES:FTP-RES-0001 | K3: ~ | L3: UNI-ROYAL | M3: 0603WAF100KT5E | N3: C22936, BASIC | P3: Preferred
A4: RES-000-1001 | B4: RES ThickF 10Ω ±1% 0.1W 0603 - BASIC | C4: 10 | D4: 0.1 | E4: ThickF | F4: 200 | G4: 1 | H4: 0603 | I4: 0-RES:SYM-RES-0000 | J4: 0-RES:FTP-RES-0001 | K4: ~ | L4: UNI-ROYAL | M4: 0603WAF100JT5E | N4: C22859, BASIC | P4: Preferred
A5: RES-000-1002 | B5: RES ThickF 100Ω ±1% 0.1W 0603 - BASIC | C5: 100 | D5: 0.1 | E5: ThickF | F5: 200 | G5: 1 | H5: 0603 | I5: 0-RES:SYM-RES-0000 | J5: 0-RES:FTP-RES-0001 | K5: ~ | L5: UNI-ROYAL | M5: 0603WAF1000T5E | N5: C22775, BASIC | P5: Preferred
A6: RES-000-1003 | B6: RES ThickF 1kΩ ±1% 0.1W 0603 - BASIC | C6: 1k | D6: 0.1 | E6: ThickF | F6: 200 | G6: 1 | H6: 0603 | I6: 0-RES:SYM-RES-0000 | J6: 0-RES:FTP-RES-0001 | K6: ~ | L6: UNI-ROYAL | M6: 0603WAF1001T5E | N6: C21190, BASIC | P6: Preferred
A7: RES-000-1004 | B7: RES ThickF 10kΩ ±1% 0.1W 0603 - BASIC | C7: 10k | D7: 0.1 | E7: ThickF | F7: 200 | G7: 1 | H7: 0603 | I7: 0-RES:SYM-RES-0000 | J7: 0-RES:FTP-RES-0001 | K7: ~ | L7: UNI-ROYAL | M7: 0603WAF1002T5E | N7: C25804, BASIC | P7: Preferred
A8: RES-000-1005 | B8: RES ThickF 100kΩ ±1% 0.1W 0603 - BASIC | C8: 100k | D8: 0.1 | E8: ThickF | F8: 200 | G8: 1 | H8: 0603 | I8: 0-RES:SYM-RES-0000 | J8: 0-RES:FTP-RES-0001 | K8: ~ | L8: UNI-ROYAL | M8: 0603WAF1003T5E | N8: C25803, BASIC | P8: Preferred
A9: RES-000-1006 | B9: RES ThickF 1MΩ ±1% 0.1W 0603 - BASIC | C9: 1M | D9: 0.1 | E9: ThickF | F9: 200 | G9: 1 | H9: 0603 | I9: 0-RES:SYM-RES-0000 | J9: 0-RES:FTP-RES-0001 | K9: ~ | L9: UNI-ROYAL | M9: 0603WAF1004T5E | N9: C22935, BASIC | P9: Preferred
A10: RES-000-1007 | B10: RES ThickF 10MΩ ±1% 0.1W 0603 - BASIC | C10: 10M | D10: 0.1 | E10: ThickF | F10: 200 | G10: 1 | H10: 0603 | I10: 0-RES:SYM-RES-0000 | J10: 0-RES:FTP-RES-0001 | K10: ~ | L10: UNI-ROYAL | M10: 0603WAF1005T5E | N10: C7250, BASIC | P10: Preferred
A11: RES-000-1651 | B11: RES ThickF 16.5Ω ±1% 0.1W 0603 | C11: 16.5 | D11: 0.1 | E11: ThickF | F11: 200 | G11: 1 | H11: 0603 | I11: 0-RES:SYM-RES-0000 | J11: 0-RES:FTP-RES-0001 | K11: ~ | L11: UNI-ROYAL | M11: 0603WAF165JT5E | N11: C12054, EXT | P11: Preferred
A12: RES-000-2006 | B12: RES ThickF 2MΩ ±1% 0.1W 0603 - BASIC | C12: 2M | D12: 0.1 | E12: ThickF | F12: 200 | G12: 1 | H12: 0603 | I12: 0-RES:SYM-RES-0000 | J12: 0-RES:FTP-RES-0001 | K12: ~ | L12: UNI-ROYAL | M12: 0603WAF2004T5E | N12: C22976, BASIC | P12: Preferred
A13: RES-000-2200 | B13: RES ThickF 2.2Ω ±1% 0.1W 0603 - BASIC | C13: 2.2 | D13: 0.1 | E13: ThickF | F13: 200 | G13: 1 | H13: 0603 | I13: 0-RES:SYM-RES-0000 | J13: 0-RES:FTP-RES-0001 | K13: ~ | L13: UNI-ROYAL | M13: 0603WAF220KT5E | N13: C22939, BASIC | P13: Preferred
A14: RES-000-2201 | B14: RES ThickF 22Ω ±1% 0.1W 0603 - BASIC | C14: 22 | D14: 0.1 | E14: ThickF | F14: 200 | G14: 1 | H14: 0603 | I14: 0-RES:SYM-RES-0000 | J14: 0-RES:FTP-RES-0001 | K14: ~ | L14: UNI-ROYAL | M14: 0603WAF220JT5E | N14: C23345, BASIC | P14: Preferred
... A29: RES-000-4705 | B29: RES ThickF 470kΩ ±1% 0.1W 0603 - BASIC | C29: 470k | D29: 0.1 | E29: ThickF | F29: 200 | G29: 1 | H29: 0603 | I29: 0-RES:SYM-RES-0000 | J29: 0-RES:FTP-RES-0001 | K29: ~ | L29: UNI-ROYAL | M29: 0603WAF4703T5E | N29: C23178, BASIC | P29: Preferred
A30: RES-000-4991 | B30: RES ThickF 49.9Ω ±1% 0.1W 0603 - BASIC | C30: 49.9 | D30: 0.1 | E30: ThickF | F30: 200 | G30: 1 | H30: 0603 | I30: 0-RES:SYM-RES-0000 | J30: 0-RES:FTP-RES-0001 | K30: ~ | L30: UNI-ROYAL | M30: 0603WAF499JT5E | N30: C23185, BASIC | P30: Preferred | Q30: Stackpole Electronics Inc | R30: RMCF0603FT49R9 | U30: Preferred
A31: RES-000-5366 | B31: RES ThickF 5.36MΩ ±1% 0.1W 0603 | C31: 5.36M | D31: 0.1 | E31: ThickF | F31: 200 | G31: 1 | H31: 0603 | I31: 0-RES:SYM-RES-0000 | J31: 0-RES:FTP-RES-0001 | K31: ~ | L31: UNI-ROYAL | M31: 0603WAF5364T5E | N31: C422919, EXT | P31: Preferred
A32: RES-000-5602 | B32: RES ThickF 560Ω ±1% 0.1W 0603 - BASIC | C32: 560 | D32: 0.1 | E32: ThickF | F32: 200 | G32: 1 | H32: 0603 | I32: 0-RES:SYM-RES-0000 | J32: 0-RES:FTP-RES-0001 | K32: ~ | L32: UNI-ROYAL | M32: 0603WAF5600T5E | N32: C23204, BASIC | P32: Preferred
A33: RES-000-5603 | B33: RES ThickF 5.6kΩ ±1% 0.1W 0603 - BASIC | C33: 5.6k | D33: 0.1 | E33: ThickF | F33: 200 | G33: 1 | H33: 0603 | I33: 0-RES:SYM-RES-0000 | J33: 0-RES:FTP-RES-0001 | K33: ~ | L33: UNI-ROYAL | M33: 0603WAF5601T5E | N33: C23189, BASIC | P33: Preferred
A34: RES-000-5604 | B34: RES ThickF 56kΩ ±1% 0.1W 0603 - BASIC | C34: 56k | D34: 0.1 | E34: ThickF | F34: 200 | G34: 1 | H34: 0603 | I34: 0-RES:SYM-RES-0000 | J34: 0-RES:FTP-RES-0001 | K34: ~ | L34: UNI-ROYAL | M34: 0603WAF5602T5E | N34: C23206, BASIC | P34: Preferred
A35: RES-000-6206 | B35: RES ThickF 6.2MΩ ±1% 0.1W 0603 | C35: 6.2M | D35: 0.1 | E35: ThickF | F35: 200 | G35: 1 | H35: 0603 | I35: 0-RES:SYM-RES-0000 | J35: 0-RES:FTP-RES-0001 | K35: ~ | L35: UNI-ROYAL | M35: 0603WAF6204T5E | N35: C54536, EXT | P35: Preferred
A36: RES-000-6802 | B36: RES ThickF 680Ω ±1% 0.1W 0603 - BASIC | C36: 680 | D36: 0.1 | E36: ThickF | F36: 200 | G36: 1 | H36: 0603 | I36: 0-RES:SYM-RES-0000 | J36: 0-RES:FTP-RES-0001 | K36: ~ | L36: UNI-ROYAL | M36: 0603WAF6800T5E | N36: C23228, BASIC | P36: Preferred
A37: RES-000-6804 | B37: RES ThickF 68kΩ ±1% 0.1W 0603 - BASIC | C37: 68k | D37: 0.1 | E37: ThickF | F37: 200 | G37: 1 | H37: 0603 | I37: 0-RES:SYM-RES-0000 | J37: 0-RES:FTP-RES-0001 | K37: ~ | L37: UNI-ROYAL | M37: 0603WAF6802T5E | N37: C23231, BASIC | P37: Preferred
A38: RES-000-7501 | B38: RES ThickF 75Ω ±1% 0.1W 0603 - BASIC | C38: 75 | D38: 0.1 | E38: ThickF | F38: 200 | G38: 1 | H38: 0603 | I38: 0-RES:SYM-RES-0000 | J38: 0-RES:FTP-RES-0001 | K38: ~ | L38: UNI-ROYAL | M38: 0603WAF750JT5E | N38: C4275, BASIC | P38: Preferred
A39: RES-001-0000 | B39: RES ThickF 0Ω ±1% 0.0625W 0402 - BASIC | C39: 0 | D39: 0.0625 | E39: ThickF | F39: 200 | G39: 1 | H39: 0402 | I39: 0-RES:SYM-RES-0000 | J39: 0-RES:FTP-RES-0000 | K39: ~ | L39: UNI-ROYAL | M39: 0402WGF0000TCE | N39: C17168, BASIC | P39: Preferred
A40: RES-001-1001 | B40: RES ThickF 10Ω ±1% 0.0625W 0402 - BASIC | C40: 10 | D40: 0.0625 | E40: ThickF | F40: 200 | G40: 1 | H40: 0402 | I40: 0-RES:SYM-RES-0000 | J40: 0-RES:FTP-RES-0000 | K40: ~ | L40: UNI-ROYAL | M40: 0402WGF100JTCE | N40: C25077, BASIC | P40: Preferred
A41: RES-001-1002 | B41: RES ThickF 100Ω ±1% 0.0625W 0402 - BASIC | C41: 100 | D41: 0.0625 | E41: ThickF | F41: 200 | G41: 1 | H41: 0402 | I41: 0-RES:SYM-RES-0000 | J41: 0-RES:FTP-RES-0000 | K41: ~ | L41: UNI-ROYAL | M41: 0402WGF1000TCE | N41: C25076, BASIC | P41: Preferred
A42: RES-001-1003 | B42: RES ThickF 1kΩ ±1% 0.0625W 0402 - BASIC | C42: 1k | D42: 0.0625 | E42: ThickF | F42: 200 | G42: 1 | H42: 0402 | I42: 0-RES:SYM-RES-0000 | J42: 0-RES:FTP-RES-0000 | K42: ~ | L42: UNI-ROYAL | M42: 0402WGF1001TCE | N42: C11702, BASIC | P42: Preferred
... A71: RES-001-6496 | B71: RES ThickF 6.49MΩ ±1% 0.0625W 0402 | C71: 6.49M | D71: 0.0625 | E71: ThickF | F71: 200 | G71: 1 | H71: 0402 | I71: 0-RES:SYM-RES-0000 | J71: 0-RES:FTP-RES-0000 | K71: ~ | L71: UNI-ROYAL | M71: 0402WGF6494TCE | N71: C38588, EXT | P71: Preferred
A72: RES-002-1002 | B72: RES Pot 100Ω 0.1W, Vertical | C72: 100 | D72: 0.1 | E72: Pot | F72: 999 | G72: 0 | H72: ~ | I72: 0-RES:SYM-RES-0001 | J72: 0-RES:FTP-RES-0003 | K72: ~ | L72: KYOCERA AVX | M72: 601010 | N72: N/A | P72: Preferred | AF72: 8/17/2025: Jelly bean THT potentiometer. Se also RM065 kits.
A73: RES-003-2700 | B73: RES ThickF 2.7Ω ±1% 0.125W 0805 | C73: 2.7 | D73: 0.125 | E73: ThickF | F73: 200 | G73: 1 | H73: 0805 | I73: 0-RES:SYM-RES-0000 | J73: 0-RES:FTP-RES-0002 | K73: ~ | L73: Stackpole Electronics | M73: RMCF0805FT2R70 | N73: C4101419, EXT | P73: Preferred | Q73: UNI-ROYAL | R73: 0805W8F270KT5E | T73: C17532, EXT | AF73: 12/13/2025: Changed RES-003 to 200ppm to make it more crossable.
A74: RES-003-6800 | B74: RES ThickF 6.8Ω ±1% 0.125W 0805 - BASIC | C74: 6.8 | D74: 0.125 | E74: ThickF | F74: 200 | G74: 1 | H74: 0805 | I74: 0-RES:SYM-RES-0000 | J74: 0-RES:FTP-RES-0002 | K74: ~ | L74: YAGEO | M74: RC0805FR-076R8L | N74: C137492, EXT | P74: Preferred
A75: RES-004-0010 | B75: RES ThickF 0.1Ω ±1% 0.25W 1206 - BASIC | C75: 0.1 | D75: 0.25 | E75: ThickF | F75: 800 | G75: 1 | H75: 1206 | I75: 0-RES:SYM-RES-0000 | J75: 0-RES:FTP-RES-0004 | K75: ~ | L75: UNI-ROYAL | M75: 1206W4F100LT5E | N75: C25334, BASIC | P75: Preferred
A76: RES-005-3656 | B76: RES ThickF 3.65MΩ ±1% 0.1W 0603 | C76: 3.65M | D76: 0.1 | E76: ThickF | F76: 100 | G76: 1 | H76: 0603 | I76: 0-RES:SYM-RES-0000 | J76: 0-RES:FTP-RES-0001 | K76: ~ | L76: UNI-ROYAL | M76: 0603WAF3654T5E | N76: C407525, EXT | P76: Preferred | Q76: YAGEO | R76: RC0603FR-073M65L | T76: C482835, EXT
A77: RES-005-3906 | B77: RES ThickF 3.9MΩ ±1% 0.1W 0603 | C77: 3.9M | D77: 0.1 | E77: ThickF | F77: 100 | G77: 1 | H77: 0603 | I77: 0-RES:SYM-RES-0000 | J77: 0-RES:FTP-RES-0001 | K77: ~ | L77: UNI-ROYAL | M77: 0603WAF3904T5E | N77: C23019, EXT | P77: Preferred
A78: RES-005-4656 | B78: RES ThickF 4.64MΩ ±1% 0.1W 0603 | C78: 4.64M | D78: 0.1 | E78: ThickF | F78: 100 | G78: 1 | H78: 0603 | I78: 0-RES:SYM-RES-0000 | J78: 0-RES:FTP-RES-0001 | K78: ~ | L78: UNI-ROYAL | M78: 0603WAF4644T5E | N78: C422925, EXT | P78: Preferred | Q78: YAGEO | R78: RC0603FR-074M64L | T78: C482862, EXT
A79: RES-005-5366 | B79: RES ThickF 5.36MΩ ±1% 0.1W 0603 | C79: 5.36M | D79: 0.1 | E79: ThickF | F79: 100 | G79: 1 | H79: 0603 | I79: 0-RES:SYM-RES-0000 | J79: 0-RES:FTP-RES-0001 | K79: ~ | L79: UNI-ROYAL | M79: 0603WAF5364T5E | N79: C422919, EXT | P79: Preferred | Q79: YAGEO | R79: RC0603FR-075M36L | T79: C482876, EXT
A80: RES-005-5626 | B80: RES ThickF 5.62MΩ ±1% 0.1W 0603 | C80: 5.62M | D80: 0.1 | E80: ThickF | F80: 100 | G80: 1 | H80: 0603 | I80: 0-RES:SYM-RES-0000 | J80: 0-RES:FTP-RES-0001 | K80: ~ | L80: UNI-ROYAL | M80: 0603WAF5624T5E | N80: C422916, EXT | P80: Preferred | Q80: YAGEO | R80: RC0603FR-075M62L | T80: C482880, EXT
A81: RES-005-5906 | B81: RES ThickF 5.9MΩ ±1% 0.1W 0603 | C81: 5.9M | D81: 0.1 | E81: ThickF | F81: 100 | G81: 1 | H81: 0603 | I81: 0-RES:SYM-RES-0000 | J81: 0-RES:FTP-RES-0001 | K81: ~ | L81: UNI-ROYAL | M81: 0603WAF5904T5E | N81: C422915, EXT | P81: Preferred
A82: RES-999-0000 | B82: PLACEHOLDER - 0603 | C82: TBD | D82: ~ | E82: ThickF | F82: ~ | G82: ~ | H82: 0603 | I82: 0-RES:SYM-RES-0000 | J82: 0-RES:FTP-RES-0001 | K82: ~ | L82: ~ | M82: ~ | N82: ~ | P82: Banned
...

Sheet RFM
A1: IPN | B1: Auto-Gen Description | C1: Description | D1: Value | E1: Case/Package Size | F1: Type | G1: Symbols | H1: Footprints | I1: Datasheet | J1: MFN_1 | K1: MPN_1 | L1: LCSC_1 | M1: LCSC_TYPE_1 | N1: Status_1 | O1: MFN_2 | P1: MPN_2 | Q1: LCSC_2 | R1: LCSC_TYPE_2 | S1: Status_2 | T1: MFN_3 | U1: MPN_3 | V1: LCSC_3 | W1: LCSC_TYPE_3 | X1: Status_3 | Y1: MFN_4 | Z1: MPN_4 | AA1: LCSC_4 | AB1: LCSC_TYPE_4 | AC1: Status_4 | AD1: Comment

Sheet RLY
A1: IPN | B1: Auto-Gen Description | C1: Description | D1: Value | E1: Case/Package Size | F1: Type | G1: Symbols | H1: Footprints | I1: Datasheet | J1: MFN_1 | K1: MPN_1 | L1: LCSC_1 | M1: LCSC_TYPE_1 | N1: Status_1 | O1: MFN_2 | P1: MPN_2 | Q1: LCSC_2 | R1: LCSC_TYPE_2 | S1: Status_2 | T1: MFN_3 | U1: MPN_3 | V1: LCSC_3 | W1: LCSC_TYPE_3 | X1: Status_3 | Y1: MFN_4 | Z1: MPN_4 | AA1: LCSC_4 | AB1: LCSC_TYPE_4 | AC1: Status_4 | AD1: Comment
A2: RLY-000-0000 | C2: Automotive Relay Socket | D2: RLY0000000 | E2: ~ | G2: 0-RLY:SYM-REL-0000 | H2: 0-RLY:FTP-RLY-0001 | I2: https://www.citrelay.com/wp-content/uploads/2025/08/Sockets.pdf | J2: CIT | K2: HD-1003 | L2: C5729356 | N2: Candidate | AD2: 11/9/2025: Beware untested footprint. Not aligned with JLC.
A3: RLY-001-0000 | C3: HV Relay Socket - 3PDT | D3: RLY0010000 | E3: ~ | G3: 0-RLY:SYM-REL-0001 | H3: 0-RLY:FTP-RLY-0000 | I3: https://assets.omron.com/m/6826d5f838b1df29/original/MJN-Datasheet.pdf | J3: OMRON | K3: PTFPCB | L3: C1524944 | N3: Candidate
A4: RLY-001-0001 | C4: HV Relay Socket - 2PDT | D4: RLY0010001 | E4: ~ | G4: 0-RLY:SYM-REL-0002 | H4: 0-RLY:FTP-RLY-0000 | I4: https://assets.omron.com/m/6826d5f838b1df29/original/MJN-Datasheet.pdf | J4: OMRON | K4: PTFPCB | L4: C1524944 | N4: Candidate | AD4: 11/9/2025 Only for DPDT MJN-series relays.

Sheet SEN
A1: IPN | B1: Auto-Gen Description | C1: Description | D1: Value | E1: Case/Package Size | F1: Type | G1: Symbols | H1: Footprints | I1: Datasheet | J1: MFN_1 | K1: MPN_1 | L1: LCSC_1 | M1: LCSC_TYPE_1 | N1: Status_1 | O1: MFN_2 | P1: MPN_2 | Q1: LCSC_2 | R1: LCSC_TYPE_2 | S1: Status_2 | T1: MFN_3 | U1: MPN_3 | V1: LCSC_3 | W1: LCSC_TYPE_3 | X1: Status_3 | Y1: MFN_4 | Z1: MPN_4 | AA1: LCSC_4 | AB1: LCSC_TYPE_4 | AC1: Status_4 | AD1: Comment

Sheet SOC
A1: IPN | B1: Auto-Gen Description | C1: Description | D1: Value | E1: Case/Package Size | F1: Type | G1: Symbols | H1: Footprints | I1: Datasheet | J1: MFN_1 | K1: MPN_1 | L1: LCSC_1 | M1: LCSC_TYPE_1 | N1: Status_1 | O1: MFN_2 | P1: MPN_2 | Q1: LCSC_2 | R1: LCSC_TYPE_2 | S1: Status_2 | T1: MFN_3 | U1: MPN_3 | V1: LCSC_3 | W1: LCSC_TYPE_3 | X1: Status_3 | Y1: MFN_4 | Z1: MPN_4 | AA1: LCSC_4 | AB1: LCSC_TYPE_4 | AC1: Status_4 | AD1: Comment

Sheet SWI
A1: IPN | B1: Auto-Gen Description | C1: Description | D1: Value | E1: Case/Package Size | F1: Type | G1: Symbols | H1: Footprints | I1: Datasheet | J1: MFN_1 | K1: MPN_1 | L1: LCSC_1 | M1: LCSC_TYPE_1 | N1: Status_1 | O1: MFN_2 | P1: MPN_2 | Q1: LCSC_TYPE_2 | R1: LCSC_2 | S1: Status_2 | T1: MFN_3 | U1: LCSC_TYPE_3 | V1: MPN_3 | W1: LCSC_3 | X1: Status_3 | Y1: LCSC_TYPE_4 | Z1: MFN_4 | AA1: MPN_4 | AB1: LCSC_4 | AC1: Status_4 | AD1: Comment
A2: SWI-101-0000 | C2: Tactile Switch, Top-actuated Model | D2: SWI1010000 | E2: 5.00x3.00 | F2: SPST | G2: 0-SWI:SYM-SWI-0000 | H2: 0-SWI:FTP-SWI-0000 | I2: ~ | J2: XUNPU | K2: TS-1088-AR02016 | L2: C720477, BASIC | N2: Preferred | O2: CIT | P2: CS1213AGF160 | R2: C6768543, EXT | S2: Candidate | AD2: 7/12/2025: Need to triple check the footprint before release.
A3: SWI-222-0000 | C3: Dip Switch, Vertical, 2Pos | D3: SWI2220000 | E3: ~ | F3: SPST | G3: 0-SWI:SYM-SWI-0002 | H3: 0-SWI:FTP-SWI-0002 | I3: https://www.sameskydevices.com/product/resource/ds01-254.pdf | J3: SAME SKY | K3: DS01-254-L-02BE | L3: N/A | N3: Candidate
A4: SWI-226-0000 | C4: Dip Switch, Vertical, 6Pos | D4: SWI2260000 | E4: ~ | F4: SPST | G4: 0-SWI:SYM-SWI-0001 | H4: 0-SWI:FTP-SWI-0001 | I4: https://www.sameskydevices.com/product/resource/ds01-254.pdf | J4: SAME SKY | K4: DS01C-254-S-06BE | L4: N/A | N4: Candidate

Sheet TRN
A1: IPN | B1: Auto-Gen Description | C1: Description | D1: Value | E1: Case/Package Size | F1: Type | G1: Symbols | H1: Footprints | I1: Datasheet | J1: MFN_1 | K1: MPN_1 | L1: LCSC_1 | M1: LCSC_TYPE_1 | N1: Status_1 | O1: MFN_2 | P1: MPN_2 | Q1: LCSC_TYPE_2 | R1: LCSC_2 | S1: Status_2 | T1: MFN_3 | U1: LCSC_TYPE_3 | V1: MPN_3 | W1: LCSC_3 | X1: Status_3 | Y1: LCSC_TYPE_4 | Z1: MFN_4 | AA1: MPN_4 | AB1: LCSC_4 | AC1: Status_4 | AD1: Comment
A2: TRN-000-0000 | C2: BJT NPN, 45Vce, 0.6A, hfe ~160 @0.1A | D2: TRN0000000 | E2: SOT23-3 | F2: BJT | G2: 0-TRN:SYM-TRN-0002 | H2: 1-PACKAGES:Generic-SOT-23-3 | I2: https://assets.nexperia.com/documents/data-sheet/BCW66X_SER.pdf | J2: Nexperia | K2: BCW66G* | L2: C549643, EXT | N2: Preferred | O2: Onsemi | P2: BCW66G* | R2: C165612, EXT | S2: Candidate
A3: TRN-000-9999 | C3: BJT, NPN, TBD | D3: TRN0009999 | E3: ~ | F3: BJT | G3: 0-TRN:SYM-TRN-0002 | H3: ~ | I3: Placeholder | J3: ~ | K3: ~ | L3: ~ | N3: Banned
A4: TRN-010-0000 | C4: NMOS 30Vds 5.7A 1.4W SOT-23-3 | D4: TRN0100000 | E4: SOT23-3 | F4: MOSFET | G4: 0-TRN:SYM-TRN-0000 | H4: 1-PACKAGES:Generic-SOT-23-3 | I4: https://mm.digikey.com/Volume0/opasdata/d220001/medias/docus/1133/AO3400A_ds.pdf | J4: Alpha & Omega | K4: AO3400A | L4: C20917, BASIC | N4: Preferred | AD4: 7/12/2025: MPN_1 is NRND, lots of similar parts available. Will need to add sources later.
A5: TRN-010-9999 | C5: MOSFET, NMOS, TBD | D5: TRN0109999 | E5: ~ | F5: MOSFET | G5: 0-TRN:SYM-TRN-0000 | H5: ~ | J5: ~ | K5: ~ | L5: ~ | N5: Banned
A6: TRN-011-0000 | C6: PMOS -20Vds 8Vgs SOT23-3 3.1A | D6: TRN0110000 | E6: SOT23-3 | F6: MOSFET | G6: 0-TRN:SYM-TRN-0001 | H6: 1-PACKAGES:Generic-SOT-23-3 | I6: https://www.vishay.com/docs/72066/si2301bds.pdf | J6: Vishay | K6: Si2301BDS-T1-*E3 | L6: C10487, BASIC | N6: Preferred
A7: TRN-011-0001 | C7: PMOS -30Vds 4A 1.4W SOT-23-3 | D7: TRN0110001 | E7: SOT23-3 | F7: MOSFET | G7: 0-TRN:SYM-TRN-0001 | H7: 1-PACKAGES:Generic-SOT-23-3 | I7: https://www.aosmd.com/sites/default/files/res/datasheets/AO3401A.pdf | J7: Alpha & Omega | K7: AO3401A | L7: C15127, BASIC | N7: Preferred
A8: TRN-011-9999 | C8: MOSFET, PMOS, TBD | D8: TRN0119999 | E8: ~ | F8: MOSFET | G8: 0-TRN:SYM-TRN-0001 | H8: ~ | J8: ~ | K8: ~ | L8: ~ | N8: Banned

Sheet _enum
A1: ana_techno | D1: cap_dielectric | G1: cap_techno | J1: dio_techno | M1: ics_techno | P1: ind_techno | S1: mfn | V1: mount_type | Y1: package | AB1: reg_techno | AE1: res_techno | AH1: status | AK1: trn_techno | AN1: lcsc_type
A2: Name | B2: Description | D2: name | E2: description | G2: name | H2: description | J2: name | K2: description | M2: name | N2: description | P2: name | Q2: description | S2: name | T2: description | V2: name | W2: description | Y2: Name | Z2: Alternate Name | AB2: name | AC2: description | AE2: name | AF2: description | AH2: name | AI2: description | AK2: name | AL2: description | AN2: name | AO2: description
A3: ADC | B3: Analog to digital converter | D3: C0G/NP0 | G3: AlumElec | H3: Aluminum Electrolytic | J3: LED | K3: Light emitting diode. | M3: Logic Level Translator | P3: Choke | S3: Alpha & Omega | V3: SCREW | Y3: 0402 | AB3: BOOST | AC3: Switching step up converter. | AE3: Pot | AF3: Potentiometer | AH3: Alternate | AI3: Tested and approved alternate. | AK3: BJT | AL3: Bipolar Junction FET | AN3: BASIC
A4: Comp | B4: Comparator | D4: X5R | G4: AlumPoly | H4: Aluminum Polymer | J4: Schottky | K4: Semiconductor-metal junction. Low Vfd, and fast recovery. | M4: Logic, AND | P4: Ferrite Bead | Q4: Ferrite bead used for filtering. | S4: Analog Devices | V4: SMD | Y4: 0603 | AB4: BUCK | AC4: Switching step down converter. | AE4: ThickF | AF4: Thick Film | AH4: Banned | AI4: Not compatible, but may be very similar. Could be used if other HW modifications were made to the circuit. | AK4: IGBT | AL4: Insulated Gate Bipolar Transistor | AN4: EXTENDED | AO4: JLCPCB charges extra fee.
A5: DAC | B5: Digital to analog converter | D5: X7R | G5: Cer | H5: Ceramic | J5: Standard | K5: Generic silicon diode. | M5: Logic, NAND | P5: Ind, Power | Q5: Power inductor. | S5: Bourns | V5: THT | Y5: 0805 | AB5: BUCK-BOOST | AC5: Switching converter, step up and down. | AE5: ThinF | AF5: Thin Film | AH5: Candidate | AI5: Untested alternate, but seems like a good part. | AK5: JFET | AL5: Junction Field Effect Transistor
A6: Opamp | B6: Operational amplifier | D6: N/A | G6: SuperCap | H6: SuperCapacitor | J6: TVS | K6: Transient voltage suppression diode. | M6: Logic, XOR | P6: Ind, Small Signal | Q6: Air core inductor used for signal conditioning. | S6: CIT | Y6: 1206 | AB6: ENERGY HARVEST | AC6: Any IC seeking to harvest energy. Solar cells ect. | AE6: Wire | AF6: Wire Wound | AH6: EOL | AI6: End of life or obsolete | AK6: MOSFET | AL6: Metal Oxide Semiconductor Field Effect Transistor
G7: Tant | H7: Tantalum | J7: Zener | M7: Loigc, OR | P7: XFRM | Q7: Transformer | S7: FH | Y7: 1210 | AB7: LDO | AC7: Linear Voltage Regulator | AH7: Preferred | AI7: Preferred part to use.
M8: Tri-State Buffer | S8: Hubei | Y8: 1812
S9: JCST | Y9: 2010
S10: KYOCERA AVX | Y10: 2512
S11: Keystone | Y11: 3.0x3.0
S12: Littlefuse | Y12: 4.0x4.0
S13: Microchip | Y13: DO-214AC | Z13: SMA
S14: Molex | Y14: SOD-123W
S15: Murata | Y15: SOD-323 | Z15: SC-76
S16: Nexperia | Y16: SOD-523
S17: OMRON | Y17: SOIC-14 (3.90mm)
S18: Onsemi | Y18: SOT-353 | Z18: 5-TSSOP, SC-70-5, SOT-353
S19: Phoenix Contact | Y19: SOT23-3
S20: Pulse Electronics | Y20: SOT23-5 | Z20: SC-74A, SOT-753
S21: Ronghe | Y21: SOT23-6
S22: SAME SKY | Y22: TSSOP-14 (4.40mm)
S23: Samsung | Y23: TSSOP-24 (4.40mm)
S24: Stackpole Electronics | Y24: VQFN-16
S25: Stackpole Electronics Inc | Y25: VQFN-24
S26: TDK | Y26: ~
S27: Taiwan Semiconductor
S28: Taiyo Yuden
S29: Texas Instruments
S30: UNI-ROYAL
S31: Vishay
S32: XUNPU
S33: YAGEO
